[2024-04-26T03:52:41.687+0000] {local_task_job_runner.py:120} INFO - ::group::Pre task execution logs
[2024-04-26T03:52:41.707+0000] {taskinstance.py:2073} INFO - Dependencies all met for dep_context=non-requeueable deps ti=<TaskInstance: Crypto_ETL.fetch_and_save_data manual__2024-04-26T03:52:34.537550+00:00 [queued]>
[2024-04-26T03:52:41.717+0000] {taskinstance.py:2073} INFO - Dependencies all met for dep_context=requeueable deps ti=<TaskInstance: Crypto_ETL.fetch_and_save_data manual__2024-04-26T03:52:34.537550+00:00 [queued]>
[2024-04-26T03:52:41.719+0000] {taskinstance.py:2303} INFO - Starting attempt 1 of 1
[2024-04-26T03:52:41.745+0000] {taskinstance.py:2327} INFO - Executing <Task(PythonOperator): fetch_and_save_data> on 2024-04-26 03:52:34.537550+00:00
[2024-04-26T03:52:41.755+0000] {warnings.py:110} WARNING - /home/***/.local/lib/python3.12/site-packages/***/task/task_runner/standard_task_runner.py:61: DeprecationWarning: This process (pid=3412) is multi-threaded, use of fork() may lead to deadlocks in the child.
  pid = os.fork()

[2024-04-26T03:52:41.758+0000] {standard_task_runner.py:90} INFO - Running: ['***', 'tasks', 'run', 'Crypto_ETL', 'fetch_and_save_data', 'manual__2024-04-26T03:52:34.537550+00:00', '--job-id', '11', '--raw', '--subdir', 'DAGS_FOLDER/processing_ETL.py', '--cfg-path', '/tmp/tmpnjadkdlo']
[2024-04-26T03:52:41.761+0000] {standard_task_runner.py:91} INFO - Job 11: Subtask fetch_and_save_data
[2024-04-26T03:52:41.760+0000] {standard_task_runner.py:63} INFO - Started process 3417 to run task
[2024-04-26T03:52:41.842+0000] {task_command.py:426} INFO - Running <TaskInstance: Crypto_ETL.fetch_and_save_data manual__2024-04-26T03:52:34.537550+00:00 [running]> on host e30f8265f0c9
[2024-04-26T03:52:41.919+0000] {taskinstance.py:2644} INFO - Exporting env vars: AIRFLOW_CTX_DAG_OWNER='***' AIRFLOW_CTX_DAG_ID='Crypto_ETL' AIRFLOW_CTX_TASK_ID='fetch_and_save_data' AIRFLOW_CTX_EXECUTION_DATE='2024-04-26T03:52:34.537550+00:00' AIRFLOW_CTX_TRY_NUMBER='1' AIRFLOW_CTX_DAG_RUN_ID='manual__2024-04-26T03:52:34.537550+00:00'
[2024-04-26T03:52:41.920+0000] {taskinstance.py:430} INFO - ::endgroup::
[2024-04-26T03:52:41.921+0000] {taskinstance.py:441} INFO - ::group::Post task execution logs
[2024-04-26T03:52:41.922+0000] {taskinstance.py:2890} ERROR - Task failed with exception
Traceback (most recent call last):
  File "/home/airflow/.local/lib/python3.12/site-packages/airflow/models/taskinstance.py", line 465, in _execute_task
    result = _execute_callable(context=context, **execute_callable_kwargs)
             ^^^^^^^^^^^^^^^^^^^^^^^^^^^^^^^^^^^^^^^^^^^^^^^^^^^^^^^^^^^^^
  File "/home/airflow/.local/lib/python3.12/site-packages/airflow/models/taskinstance.py", line 432, in _execute_callable
    return execute_callable(context=context, **execute_callable_kwargs)
           ^^^^^^^^^^^^^^^^^^^^^^^^^^^^^^^^^^^^^^^^^^^^^^^^^^^^^^^^^^^^
  File "/home/airflow/.local/lib/python3.12/site-packages/airflow/models/baseoperator.py", line 400, in wrapper
    return func(self, *args, **kwargs)
           ^^^^^^^^^^^^^^^^^^^^^^^^^^^
  File "/home/airflow/.local/lib/python3.12/site-packages/airflow/operators/python.py", line 235, in execute
    return_value = self.execute_callable()
                   ^^^^^^^^^^^^^^^^^^^^^^^
  File "/home/airflow/.local/lib/python3.12/site-packages/airflow/operators/python.py", line 252, in execute_callable
    return self.python_callable(*self.op_args, **self.op_kwargs)
           ^^^^^^^^^^^^^^^^^^^^^^^^^^^^^^^^^^^^^^^^^^^^^^^^^^^^^
  File "/opt/airflow/dags/processing_ETL.py", line 40, in _fetch_and_save_data
    binance_data = _get_data()
                   ^^^^^^^^^^^
  File "/opt/airflow/dags/processing_ETL.py", line 27, in _get_data
    with open("/tmp/download.json") as f:
         ^^^^^^^^^^^^^^^^^^^^^^^^^^
FileNotFoundError: [Errno 2] No such file or directory: '/tmp/download.json'
[2024-04-26T03:52:41.935+0000] {taskinstance.py:1205} INFO - Marking task as FAILED. dag_id=Crypto_ETL, task_id=fetch_and_save_data, execution_date=20240426T035234, start_date=20240426T035241, end_date=20240426T035241
[2024-04-26T03:52:41.952+0000] {standard_task_runner.py:110} ERROR - Failed to execute job 11 for task fetch_and_save_data ([Errno 2] No such file or directory: '/tmp/download.json'; 3417)
[2024-04-26T03:52:41.978+0000] {local_task_job_runner.py:240} INFO - Task exited with return code 1
[2024-04-26T03:52:41.991+0000] {taskinstance.py:3482} INFO - 0 downstream tasks scheduled from follow-on schedule check
[2024-04-26T03:52:41.993+0000] {local_task_job_runner.py:222} INFO - ::endgroup::
