[2024-04-26T07:00:58.881+0000] {local_task_job_runner.py:120} INFO - ::group::Pre task execution logs
[2024-04-26T07:00:58.900+0000] {taskinstance.py:2073} INFO - Dependencies all met for dep_context=non-requeueable deps ti=<TaskInstance: Crypto_ETL.concat_datasets manual__2024-04-26T07:00:41.683023+00:00 [queued]>
[2024-04-26T07:00:58.909+0000] {taskinstance.py:2073} INFO - Dependencies all met for dep_context=requeueable deps ti=<TaskInstance: Crypto_ETL.concat_datasets manual__2024-04-26T07:00:41.683023+00:00 [queued]>
[2024-04-26T07:00:58.909+0000] {taskinstance.py:2303} INFO - Starting attempt 1 of 1
[2024-04-26T07:00:58.922+0000] {taskinstance.py:2327} INFO - Executing <Task(PythonOperator): concat_datasets> on 2024-04-26 07:00:41.683023+00:00
[2024-04-26T07:00:58.929+0000] {warnings.py:110} WARNING - /home/***/.local/lib/python3.12/site-packages/***/task/task_runner/standard_task_runner.py:61: DeprecationWarning: This process (pid=5860) is multi-threaded, use of fork() may lead to deadlocks in the child.
  pid = os.fork()

[2024-04-26T07:00:58.931+0000] {standard_task_runner.py:63} INFO - Started process 5862 to run task
[2024-04-26T07:00:58.931+0000] {standard_task_runner.py:90} INFO - Running: ['***', 'tasks', 'run', 'Crypto_ETL', 'concat_datasets', 'manual__2024-04-26T07:00:41.683023+00:00', '--job-id', '28', '--raw', '--subdir', 'DAGS_FOLDER/processing_ETL.py', '--cfg-path', '/tmp/tmpp51uzsl9']
[2024-04-26T07:00:58.932+0000] {standard_task_runner.py:91} INFO - Job 28: Subtask concat_datasets
[2024-04-26T07:00:58.973+0000] {task_command.py:426} INFO - Running <TaskInstance: Crypto_ETL.concat_datasets manual__2024-04-26T07:00:41.683023+00:00 [running]> on host e30f8265f0c9
[2024-04-26T07:00:59.049+0000] {taskinstance.py:2644} INFO - Exporting env vars: AIRFLOW_CTX_DAG_OWNER='***' AIRFLOW_CTX_DAG_ID='Crypto_ETL' AIRFLOW_CTX_TASK_ID='concat_datasets' AIRFLOW_CTX_EXECUTION_DATE='2024-04-26T07:00:41.683023+00:00' AIRFLOW_CTX_TRY_NUMBER='1' AIRFLOW_CTX_DAG_RUN_ID='manual__2024-04-26T07:00:41.683023+00:00'
[2024-04-26T07:00:59.051+0000] {taskinstance.py:430} INFO - ::endgroup::
[2024-04-26T07:00:59.097+0000] {python.py:237} INFO - Done. Returned value was:                     Date    Price  ...   Volume  ChangePercentFromLastMonth
0             12/19/2023  42259.3  ...   55.29K                       -0.94
1             12/18/2023  42659.7  ...   61.58K                        3.12
2             12/17/2023  41368.7  ...   35.46K                       -2.14
3             12/16/2023  42271.7  ...   30.11K                        0.82
4             12/15/2023  41929.0  ...   45.28K                       -2.55
..                   ...      ...  ...      ...                         ...
133  2010-12-01 00:00:00      0.3  ...  263.65K                       44.09
134  2010-11-01 00:00:00      0.2  ...  826.25K                        0.00
135  2010-10-01 00:00:00      0.2  ...    1.11M                      210.99
136  2010-09-01 00:00:00      0.1  ...  216.81K                        0.00
137  2010-08-01 00:00:00      0.1  ...  221.74K                        0.00

[937 rows x 7 columns]
[2024-04-26T07:00:59.116+0000] {taskinstance.py:441} INFO - ::group::Post task execution logs
[2024-04-26T07:00:59.138+0000] {xcom.py:677} ERROR - Object of type DataFrame is not JSON serializable. If you are using pickle instead of JSON for XCom, then you need to enable pickle support for XCom in your *** config or make sure to decorate your object with attr.
[2024-04-26T07:00:59.139+0000] {taskinstance.py:2890} ERROR - Task failed with exception
Traceback (most recent call last):
  File "/home/airflow/.local/lib/python3.12/site-packages/airflow/utils/json.py", line 91, in default
    return serialize(o)
           ^^^^^^^^^^^^
  File "/home/airflow/.local/lib/python3.12/site-packages/airflow/serialization/serde.py", line 148, in serialize
    data, serialized_classname, version, is_serialized = _serializers[qn].serialize(o)
                                                         ^^^^^^^^^^^^^^^^^^^^^^^^^^^^^
  File "/home/airflow/.local/lib/python3.12/site-packages/airflow/serialization/serializers/pandas.py", line 49, in serialize
    table = pa.Table.from_pandas(o)
            ^^^^^^^^^^^^^^^^^^^^^^^
  File "pyarrow/table.pxi", line 3874, in pyarrow.lib.Table.from_pandas
  File "/home/airflow/.local/lib/python3.12/site-packages/pyarrow/pandas_compat.py", line 624, in dataframe_to_arrays
    arrays[i] = maybe_fut.result()
                ^^^^^^^^^^^^^^^^^^
  File "/usr/local/lib/python3.12/concurrent/futures/_base.py", line 449, in result
    return self.__get_result()
           ^^^^^^^^^^^^^^^^^^^
  File "/usr/local/lib/python3.12/concurrent/futures/_base.py", line 401, in __get_result
    raise self._exception
  File "/usr/local/lib/python3.12/concurrent/futures/thread.py", line 58, in run
    result = self.fn(*self.args, **self.kwargs)
             ^^^^^^^^^^^^^^^^^^^^^^^^^^^^^^^^^^
  File "/home/airflow/.local/lib/python3.12/site-packages/pyarrow/pandas_compat.py", line 598, in convert_column
    raise e
  File "/home/airflow/.local/lib/python3.12/site-packages/pyarrow/pandas_compat.py", line 592, in convert_column
    result = pa.array(col, type=type_, from_pandas=True, safe=safe)
             ^^^^^^^^^^^^^^^^^^^^^^^^^^^^^^^^^^^^^^^^^^^^^^^^^^^^^^
  File "pyarrow/array.pxi", line 339, in pyarrow.lib.array
  File "pyarrow/array.pxi", line 85, in pyarrow.lib._ndarray_to_array
  File "pyarrow/error.pxi", line 91, in pyarrow.lib.check_status
pyarrow.lib.ArrowTypeError: ("Expected bytes, got a 'Timestamp' object", 'Conversion failed for column Date with type object')

During handling of the above exception, another exception occurred:

Traceback (most recent call last):
  File "/home/airflow/.local/lib/python3.12/site-packages/airflow/models/taskinstance.py", line 486, in _execute_task
    task_instance.xcom_push(key=XCOM_RETURN_KEY, value=xcom_value, session=session)
  File "/home/airflow/.local/lib/python3.12/site-packages/airflow/utils/session.py", line 76, in wrapper
    return func(*args, **kwargs)
           ^^^^^^^^^^^^^^^^^^^^^
  File "/home/airflow/.local/lib/python3.12/site-packages/airflow/models/taskinstance.py", line 3182, in xcom_push
    XCom.set(
  File "/home/airflow/.local/lib/python3.12/site-packages/airflow/utils/session.py", line 76, in wrapper
    return func(*args, **kwargs)
           ^^^^^^^^^^^^^^^^^^^^^
  File "/home/airflow/.local/lib/python3.12/site-packages/airflow/models/xcom.py", line 247, in set
    value = cls.serialize_value(
            ^^^^^^^^^^^^^^^^^^^^
  File "/home/airflow/.local/lib/python3.12/site-packages/airflow/models/xcom.py", line 675, in serialize_value
    return json.dumps(value, cls=XComEncoder).encode("UTF-8")
           ^^^^^^^^^^^^^^^^^^^^^^^^^^^^^^^^^^
  File "/usr/local/lib/python3.12/json/__init__.py", line 238, in dumps
    **kw).encode(obj)
          ^^^^^^^^^^^
  File "/home/airflow/.local/lib/python3.12/site-packages/airflow/utils/json.py", line 104, in encode
    return super().encode(o)
           ^^^^^^^^^^^^^^^^^
  File "/usr/local/lib/python3.12/json/encoder.py", line 200, in encode
    chunks = self.iterencode(o, _one_shot=True)
             ^^^^^^^^^^^^^^^^^^^^^^^^^^^^^^^^^^
  File "/usr/local/lib/python3.12/json/encoder.py", line 258, in iterencode
    return _iterencode(o, 0)
           ^^^^^^^^^^^^^^^^^
  File "/home/airflow/.local/lib/python3.12/site-packages/airflow/utils/json.py", line 93, in default
    return super().default(o)
           ^^^^^^^^^^^^^^^^^^
  File "/usr/local/lib/python3.12/json/encoder.py", line 180, in default
    raise TypeError(f'Object of type {o.__class__.__name__} '
TypeError: Object of type DataFrame is not JSON serializable
[2024-04-26T07:00:59.154+0000] {taskinstance.py:1205} INFO - Marking task as FAILED. dag_id=Crypto_ETL, task_id=concat_datasets, execution_date=20240426T070041, start_date=20240426T070058, end_date=20240426T070059
[2024-04-26T07:00:59.165+0000] {standard_task_runner.py:110} ERROR - Failed to execute job 28 for task concat_datasets (Object of type DataFrame is not JSON serializable; 5862)
[2024-04-26T07:00:59.185+0000] {local_task_job_runner.py:240} INFO - Task exited with return code 1
[2024-04-26T07:00:59.200+0000] {taskinstance.py:3482} INFO - 0 downstream tasks scheduled from follow-on schedule check
[2024-04-26T07:00:59.203+0000] {local_task_job_runner.py:222} INFO - ::endgroup::
