[2024-04-26T04:54:01.738+0000] {local_task_job_runner.py:120} INFO - ::group::Pre task execution logs
[2024-04-26T04:54:01.760+0000] {taskinstance.py:2073} INFO - Dependencies all met for dep_context=non-requeueable deps ti=<TaskInstance: Crypto_ETL.fetch_and_save_data manual__2024-04-26T04:19:49.652646+00:00 [queued]>
[2024-04-26T04:54:01.768+0000] {taskinstance.py:2073} INFO - Dependencies all met for dep_context=requeueable deps ti=<TaskInstance: Crypto_ETL.fetch_and_save_data manual__2024-04-26T04:19:49.652646+00:00 [queued]>
[2024-04-26T04:54:01.768+0000] {taskinstance.py:2303} INFO - Starting attempt 3 of 3
[2024-04-26T04:54:01.784+0000] {taskinstance.py:2327} INFO - Executing <Task(PythonOperator): fetch_and_save_data> on 2024-04-26 04:19:49.652646+00:00
[2024-04-26T04:54:01.792+0000] {warnings.py:110} WARNING - /home/***/.local/lib/python3.12/site-packages/***/task/task_runner/standard_task_runner.py:61: DeprecationWarning: This process (pid=4236) is multi-threaded, use of fork() may lead to deadlocks in the child.
  pid = os.fork()

[2024-04-26T04:54:01.793+0000] {standard_task_runner.py:63} INFO - Started process 4238 to run task
[2024-04-26T04:54:01.793+0000] {standard_task_runner.py:90} INFO - Running: ['***', 'tasks', 'run', 'Crypto_ETL', 'fetch_and_save_data', 'manual__2024-04-26T04:19:49.652646+00:00', '--job-id', '21', '--raw', '--subdir', 'DAGS_FOLDER/processing_ETL.py', '--cfg-path', '/tmp/tmp_18bdogl']
[2024-04-26T04:54:01.795+0000] {standard_task_runner.py:91} INFO - Job 21: Subtask fetch_and_save_data
[2024-04-26T04:54:01.840+0000] {task_command.py:426} INFO - Running <TaskInstance: Crypto_ETL.fetch_and_save_data manual__2024-04-26T04:19:49.652646+00:00 [running]> on host e30f8265f0c9
[2024-04-26T04:54:01.932+0000] {taskinstance.py:2644} INFO - Exporting env vars: AIRFLOW_CTX_DAG_OWNER='***' AIRFLOW_CTX_DAG_ID='Crypto_ETL' AIRFLOW_CTX_TASK_ID='fetch_and_save_data' AIRFLOW_CTX_EXECUTION_DATE='2024-04-26T04:19:49.652646+00:00' AIRFLOW_CTX_TRY_NUMBER='3' AIRFLOW_CTX_DAG_RUN_ID='manual__2024-04-26T04:19:49.652646+00:00'
[2024-04-26T04:54:01.934+0000] {taskinstance.py:430} INFO - ::endgroup::
[2024-04-26T04:54:01.943+0000] {taskinstance.py:441} INFO - ::group::Post task execution logs
[2024-04-26T04:54:01.944+0000] {taskinstance.py:2890} ERROR - Task failed with exception
Traceback (most recent call last):
  File "/home/airflow/.local/lib/python3.12/site-packages/airflow/models/taskinstance.py", line 465, in _execute_task
    result = _execute_callable(context=context, **execute_callable_kwargs)
             ^^^^^^^^^^^^^^^^^^^^^^^^^^^^^^^^^^^^^^^^^^^^^^^^^^^^^^^^^^^^^
  File "/home/airflow/.local/lib/python3.12/site-packages/airflow/models/taskinstance.py", line 432, in _execute_callable
    return execute_callable(context=context, **execute_callable_kwargs)
           ^^^^^^^^^^^^^^^^^^^^^^^^^^^^^^^^^^^^^^^^^^^^^^^^^^^^^^^^^^^^
  File "/home/airflow/.local/lib/python3.12/site-packages/airflow/models/baseoperator.py", line 400, in wrapper
    return func(self, *args, **kwargs)
           ^^^^^^^^^^^^^^^^^^^^^^^^^^^
  File "/home/airflow/.local/lib/python3.12/site-packages/airflow/operators/python.py", line 235, in execute
    return_value = self.execute_callable()
                   ^^^^^^^^^^^^^^^^^^^^^^^
  File "/home/airflow/.local/lib/python3.12/site-packages/airflow/operators/python.py", line 252, in execute_callable
    return self.python_callable(*self.op_args, **self.op_kwargs)
           ^^^^^^^^^^^^^^^^^^^^^^^^^^^^^^^^^^^^^^^^^^^^^^^^^^^^^
  File "/opt/airflow/dags/processing_ETL.py", line 51, in _fetch_and_save_data
    binance_to_csv(binance_data)
  File "/opt/airflow/dags/processing_ETL.py", line 43, in binance_to_csv
    df.to_csv("/opt/airflow-docker/dags/binance_dataset.csv", index=False)
  File "/home/airflow/.local/lib/python3.12/site-packages/pandas/core/generic.py", line 3902, in to_csv
    return DataFrameRenderer(formatter).to_csv(
           ^^^^^^^^^^^^^^^^^^^^^^^^^^^^^^^^^^^^
  File "/home/airflow/.local/lib/python3.12/site-packages/pandas/io/formats/format.py", line 1152, in to_csv
    csv_formatter.save()
  File "/home/airflow/.local/lib/python3.12/site-packages/pandas/io/formats/csvs.py", line 247, in save
    with get_handle(
         ^^^^^^^^^^^
  File "/home/airflow/.local/lib/python3.12/site-packages/pandas/io/common.py", line 739, in get_handle
    check_parent_directory(str(handle))
  File "/home/airflow/.local/lib/python3.12/site-packages/pandas/io/common.py", line 604, in check_parent_directory
    raise OSError(rf"Cannot save file into a non-existent directory: '{parent}'")
OSError: Cannot save file into a non-existent directory: '/opt/***-docker/dags'
[2024-04-26T04:54:01.965+0000] {taskinstance.py:1205} INFO - Marking task as FAILED. dag_id=Crypto_ETL, task_id=fetch_and_save_data, execution_date=20240426T041949, start_date=20240426T045401, end_date=20240426T045401
[2024-04-26T04:54:01.981+0000] {standard_task_runner.py:110} ERROR - Failed to execute job 21 for task fetch_and_save_data (Cannot save file into a non-existent directory: '/opt/***-docker/dags'; 4238)
[2024-04-26T04:54:02.008+0000] {local_task_job_runner.py:240} INFO - Task exited with return code 1
[2024-04-26T04:54:02.033+0000] {taskinstance.py:3482} INFO - 0 downstream tasks scheduled from follow-on schedule check
[2024-04-26T04:54:02.035+0000] {local_task_job_runner.py:222} INFO - ::endgroup::
